Workbook

Sheet Dashboard
A1: 财务与人力资源推演模型 - Dashboard
A3: 参数输入区
A5: 1.1 薪酬参数 (Compensation Parameters)
A6: 参数名称 | B6: 默认值 | C6: 单位 | D6: 描述与来源
A7: 制作节点
A8: 内审通过基础薪酬 | B8: 5 | C8: 元/工作单位 | D8: 基于完成并通过内审的报酬 (引用元规则 XC-1-1 参数1)
A9: 外审通过额外薪酬 | B9: 10 | C9: 元/工作单位 | D9: 交付成果最终通过外审的额外奖励 (引用元规则 XC-1-1 参数2)
A10: S级月度奖金 | B10: 500 | C10: 元/月 | D10: 当月保持S级状态获得的固定奖金 (引用元规则 XC-1-2 参数1)
A11: 培训节点
A12: 团队服务内审薪酬 | B12: 0 | C12: 元/工作单位 | D12: 基于团队完成的工作单位，给培训节点的内审部分提成 (引用元规则 XC-1-1 参数1)
A13: 团队服务外审薪酬 | B13: 1 | C13: 元/工作单位 | D13: 基于团队完成的工作单位，给培训节点的外审部分提成 (引用元规则 XC-1-1 参数2)
A14: S级团队保持奖金 | B14: 100 | C14: 元/人 | D14: 根据月末团队中S级成员数量发放的奖金 (引用元规则 XC-1-2 参数1)
A15: 完成基础培训薪酬 | B15: 100 | C15: 元/人 | D15: 成功完成一名组员的基础培训所得奖励 (引用元规则 XC-2-1 参数1)
A16: 新晋升S级培训薪酬 | B16: 200 | C16: 元/人 | D16: 成功将一名组员培养至S级所得奖励 (引用元规则 XC-2-1 参数2)
A17: 节点晋升激励奖金 | B17: 1000 | C17: 元/人 | D17: 培养的组员晋升为新培训节点时的一次性奖励 (引用元规则 XC-2-2 参数1)
A18: 内审节点
A19: 有效审核薪酬 | B19: -4 | C19: 元/次 | D19: 内审通过后，一次性通过外审的审核报酬 (引用元规则 XC-3-1 参数1)
A20: 无效审核薪酬 | B20: 0 | C20: 元/次 | D20: 内审通过后，未能一次性通过外审的审核报酬 (引用元规则 XC-3-1 参数2)
A21: 项目管理节点
A22: 订单全流程跟踪费 | B22: 1 | C22: 元/单 | D22: 完整跟进一个订单全流程的报酬 (引用元规则 XC-4-1 参数1)
A25: 1.2 业务核心参数 (Core Business Parameters)
A26: 参数名称 | B26: 默认值 | C26: 单位 | D26: 描述
A27: 订单定价 | B27: 30 | C27: 元/工作单位 | D27: 我们对客户就每个工作单位的报价
A28: 平均弃单率 | B28: 0.2 | C28: % | D28: 制作节点在任务周期内放弃订单的平均比率
A29: 平均外审一次通过率 | B29: 0.4 | C29: % | D29: 内审通过的订单，首次提交给甲方审核的通过率
A30: 平均外审通过率 | B30: 0.95 | C30: % | D30: 订单最终通过外审的比率
A31: 平均内审次数 | B31: 1.5 | C31: 次/工作单位 | D31: 单个工作单位从首次提交到通过内审，平均需要经历的内审次数
A34: 1.3 人力与效率参数 (HR & Efficiency Parameters)
A36: 1.3.1 产能与规模 (Capacity & Scale)
A37: 参数名称 | B37: 默认值 | C37: 单位 | D37: 描述
A38: 制作节点
A39: 月度工作单位容量 | B39: 150 | C39: 工作单位/月 | D39: 一位标准的S级制作节点一个月的平均产能
A40: 培训节点
A41: 团队规模 | B41: 20 | C41: 人/团队 | D41: 一位培训节点平均带领的制作节点数量
A42: 内审节点
A43: 月度审核总次数 | B43: 2000 | C43: 次/月 | D43: 一位标准的内审节点一个月的平均审核次数
A44: 项目管理节点
A45: 月度跟踪订单总数 | B45: 1000 | C45: 单/月 | D45: 一位标准的项目管理节点一个月的平均跟踪订单数
A46: 运营模拟
A47: 总S级制作节点数 | B47: 30 | C47: 人 | D47: 用于模拟计算整体项目毛利率的团队规模基数
...

Sheet 模型计算
A1: 模型计算引擎 (Calculation Engine)
A3: 区域A：参数链接区
A5: 1.1 薪酬参数
A6: 参数名称 | B6: 数值 | C6: 单位
A7: 制作节点
A8: 内审通过基础薪酬 | B8: =Dashboard!B8 -> 5 | C8: 元/工作单位
A9: 外审通过额外薪酬 | B9: =Dashboard!B9 -> 10 | C9: 元/工作单位
A10: S级月度奖金 | B10: =Dashboard!B10 -> 500 | C10: 元/月
A11: 培训节点
A12: 团队服务内审薪酬 | B12: =Dashboard!B12 -> 0 | C12: 元/工作单位
A13: 团队服务外审薪酬 | B13: =Dashboard!B13 -> 1 | C13: 元/工作单位
A14: S级团队保持奖金 | B14: =Dashboard!B14 -> 100 | C14: 元/人
A15: 完成基础培训薪酬 | B15: =Dashboard!B15 -> 100 | C15: 元/人
A16: 新晋升S级培训薪酬 | B16: =Dashboard!B16 -> 200 | C16: 元/人
A17: 节点晋升激励奖金 | B17: =Dashboard!B17 -> 1000 | C17: 元/人
A18: 内审节点
A19: 有效审核薪酬 | B19: =Dashboard!B19 -> -4 | C19: 元/次
A20: 无效审核薪酬 | B20: =Dashboard!B20 -> 0 | C20: 元/次
A21: 项目管理节点
A22: 订单全流程跟踪费 | B22: =Dashboard!B22 -> 1 | C22: 元/单
A25: 1.2 业务核心参数
A26: 参数名称 | B26: 数值 | C26: 单位
A27: 订单定价 | B27: =Dashboard!B27 -> 30 | C27: 元/工作单位
A28: 平均弃单率 | B28: =Dashboard!B28 -> 0.2 | C28: %
A29: 平均外审一次通过率 | B29: =Dashboard!B29 -> 0.4 | C29: %
A30: 平均外审通过率 | B30: =Dashboard!B30 -> 0.95 | C30: %
A31: 平均内审次数 | B31: =Dashboard!B31 -> 1.5 | C31: 次/工作单位
A34: 1.3 人力与效率参数
A36: 1.3.1 产能与规模
A37: 参数名称 | B37: 数值 | C37: 单位
A38: 制作节点
A39: 月度工作单位容量 | B39: =Dashboard!B39 -> 150 | C39: 工作单位/月
A40: 培训节点
A41: 团队规模 | B41: =Dashboard!B41 -> 20 | C41: 人/团队
A42: 内审节点
A43: 月度审核总次数 | B43: =Dashboard!B43 -> 2000 | C43: 次/月
A44: 项目管理节点
A45: 月度跟踪订单总数 | B45: =Dashboard!B45 -> 1000 | C45: 单/月
A46: 运营模拟
A47: 总S级制作节点数 | B47: =Dashboard!B47 -> 30 | C47: 人
...

Sheet 数据源
A1: 数据源 (Data Sources)
A3: 角色列表
A4: 制作节点
A5: 培训节点
A6: 内审节点
A7: 项目管理节点
A9: 参数单位列表
A10: 元/工作单位
A11: 元/月
A12: 元/人
A13: 元/次
A14: 元/单
... A27: 小时/人/月
